Workbook

Sheet Prices
A1: Date | B1: MSFT Close (USD) | C1: ORCL Close (USD) | D1: SONY Close (USD)
A2: 46101 | B2: 381.87 | C2: 149.68 | D2: 20.22
A3: 46100 | B3: 389.02 | C3: 155.52 | D3: 20.62
A4: 46099 | B4: 391.79 | C4: 152.9 | D4: 20.38
A5: 46098 | B5: 399.41 | C5: 154.69 | D5: 20.92
A6: 46097 | B6: 399.95 | C6: 155.97 | D6: 21.65
A7: 46094 | B7: 395.55 | C7: 155.11 | D7: 21.49
A8: 46093 | B8: 401.86 | C8: 159.16 | D8: 21.46
A9: 46092 | B9: 404.88 | C9: 163.12 | D9: 21.49
A10: 46091 | B10: 405.76 | C10: 149.4 | D10: 21.68
A11: 46090 | B11: 409.41 | C11: 151.56 | D11: 21.62
A12: 46087 | B12: 408.96 | C12: 152.96 | D12: 21.48
A13: 46086 | B13: 410.68 | C13: 154.79 | D13: 21.37
... A251: 45740 | B251: 393.08 | C251: 154.87 | D251: 24.6421

Sheet Returns
A1: Date | B1: MSFT Return (USD) | C1: ORCL Return (USD) | D1: SONY Return (USD)
A3: =Prices!A3 -> 46100 | B3: =LN(Prices!B2)-LN(Prices!B3) -> -0.01855052 | C3: =LN(Prices!C2)-LN(Prices!C3) -> -0.038274659 | D3: =LN(Prices!D2)-LN(Prices!D3) -> -0.019589265
A4: =Prices!A4 -> 46099 | B4: =LN(Prices!B3)-LN(Prices!B4) -> -0.0070952258 | C4: =LN(Prices!C3)-LN(Prices!C4) -> 0.016990228 | D4: =LN(Prices!D3)-LN(Prices!D4) -> 0.011707451
A5: =Prices!A5 -> 46098 | B5: =LN(Prices!B4)-LN(Prices!B5) -> -0.019262476 | C5: =LN(Prices!C4)-LN(Prices!C5) -> -0.011639001 | D5: =LN(Prices!D4)-LN(Prices!D5) -> -0.026151611
A6: =Prices!A6 -> 46097 | B6: =LN(Prices!B5)-LN(Prices!B6) -> -0.0013510811 | C6: =LN(Prices!C5)-LN(Prices!C6) -> -0.0082405668 | D6: =LN(Prices!D5)-LN(Prices!D6) -> -0.034299815
A7: =Prices!A7 -> 46094 | B7: =LN(Prices!B6)-LN(Prices!B7) -> 0.011062338 | C7: =LN(Prices!C6)-LN(Prices!C7) -> 0.0055291384 | D7: =LN(Prices!D6)-LN(Prices!D7) -> 0.0074177438
A8: =Prices!A8 -> 46093 | B8: =LN(Prices!B7)-LN(Prices!B8) -> -0.015826568 | C8: =LN(Prices!C7)-LN(Prices!C8) -> -0.025775443 | D8: =LN(Prices!D7)-LN(Prices!D8) -> 0.0013969735
A9: =Prices!A9 -> 46092 | B9: =LN(Prices!B8)-LN(Prices!B9) -> -0.0074869576 | C9: =LN(Prices!C8)-LN(Prices!C9) -> -0.024576141 | D9: =LN(Prices!D8)-LN(Prices!D9) -> -0.0013969735
A10: =Prices!A10 -> 46091 | B10: =LN(Prices!B9)-LN(Prices!B10) -> -0.0021711249 | C10: =LN(Prices!C9)-LN(Prices!C10) -> 0.087858854 | D10: =LN(Prices!D9)-LN(Prices!D10) -> -0.0088024659
A11: =Prices!A11 -> 46090 | B11: =LN(Prices!B10)-LN(Prices!B11) -> -0.0089552471 | C11: =LN(Prices!C10)-LN(Prices!C11) -> -0.014354313 | D11: =LN(Prices!D10)-LN(Prices!D11) -> 0.0027713644
A12: =Prices!A12 -> 46087 | B12: =LN(Prices!B11)-LN(Prices!B12) -> 0.0010997472 | C12: =LN(Prices!C11)-LN(Prices!C12) -> -0.0091948632 | D12: =LN(Prices!D11)-LN(Prices!D12) -> 0.0064965426
A13: =Prices!A13 -> 46086 | B13: =LN(Prices!B12)-LN(Prices!B13) -> -0.0041969707 | C13: =LN(Prices!C12)-LN(Prices!C13) -> -0.01189291 | D13: =LN(Prices!D12)-LN(Prices!D13) -> 0.0051342003
A14: =Prices!A14 -> 46085 | B14: =LN(Prices!B13)-LN(Prices!B14) -> 0.01343355 | C14: =LN(Prices!C13)-LN(Prices!C14) -> 0.015757586 | D14: =LN(Prices!D13)-LN(Prices!D14) -> -0.028599735
... A251: =Prices!A251 -> 45740 | B251: =LN(Prices!B250)-LN(Prices!B251) -> 0.0052775927 | C251: =LN(Prices!C250)-LN(Prices!C251) -> -0.0060881017 | D251: =LN(Prices!D250)-LN(Prices!D251) -> -0.00039777248

Sheet Statistics
A1: Descriptive Statistics
A4: Stock | B4: Mean Return | C4: Variance | D4: Std Dev
A5: Microsoft | B5: =AVERAGE(Returns!B3:B251) -> -0.00011619645 | C5: =_xlfn.VAR.S(Returns!B3:B251) -> 0.00027529141 | D5: =_xlfn.STDEV.S(Returns!B3:B251) -> 0.016591908
A6: Oracle | B6: =AVERAGE(Returns!C3:C251) -> -0.00013689307 | C6: =_xlfn.VAR.S(Returns!C3:C251) -> 0.0013686392 | D6: =_xlfn.STDEV.S(Returns!C3:C251) -> 0.036995124
A7: Sony | B7: =AVERAGE(Returns!D3:D251) -> -0.00079431385 | C7: =_xlfn.VAR.S(Returns!D3:D251) -> 0.00036628586 | D7: =_xlfn.STDEV.S(Returns!D3:D251) -> 0.019138596
A9: Covariance Matrix
A11: Column1 | B11: Microsoft | C11: Oracle | D11: Sony
A12: Microsoft | B12: =_xlfn.COVARIANCE.S(Returns!B3:B251,Returns!B3:B251) -> 0.00027529141 | C12: =_xlfn.COVARIANCE.S(Returns!B3:B251,Returns!C3:C251) -> 0.00024862063 | D12: =_xlfn.COVARIANCE.S(Returns!B3:B251,Returns!D3:D251) -> 8.9273997e-05
A13: Oracle | B13: =_xlfn.COVARIANCE.S(Returns!C3:C251,Returns!B3:B251) -> 0.00024862063 | C13: =_xlfn.COVARIANCE.S(Returns!C3:C251,Returns!C3:C251) -> 0.0013686392 | D13: =_xlfn.COVARIANCE.S(Returns!C3:C251,Returns!D3:D251) -> 0.00014468916
A14: Sony | B14: =_xlfn.COVARIANCE.S(Returns!D3:D251,Returns!B3:B251) -> 8.9273997e-05 | C14: =_xlfn.COVARIANCE.S(Returns!D3:D251,Returns!C3:C251) -> 0.00014468916 | D14: =_xlfn.COVARIANCE.S(Returns!D3:D251,Returns!D3:D251) -> 0.00036628586
A16: Correlation Matrix
A18: Column1 | B18: Microsoft | C18: Oracle | D18: Sony
A19: Microsoft | B19: =CORREL(Returns!B3:B251,Returns!B3:B251) -> 1 | C19: =CORREL(Returns!B3:B251,Returns!C3:C251) -> 0.40503853 | D19: =CORREL(Returns!B3:B251,Returns!D3:D251) -> 0.28113736
A20: Oracle | B20: =CORREL(Returns!C3:C251,Returns!B3:B251) -> 0.40503853 | C20: =CORREL(Returns!C3:C251,Returns!C3:C251) -> 1 | D20: =CORREL(Returns!C3:C251,Returns!D3:D251) -> 0.20435319
A21: Sony | B21: =CORREL(Returns!D3:D251,Returns!B3:B251) -> 0.28113736 | C21: =CORREL(Returns!D3:D251,Returns!C3:C251) -> 0.20435319 | D21: =CORREL(Returns!D3:D251,Returns!D3:D251) -> 1

Sheet Portfolio Weights Returns
A1: Weights
A2: w1 | B2: 0 | D2: Expected return on portfolio | G2: =( B2 * Statistics!B5 ) + ( B3 * Statistics!B6 ) + ( B4 * Statistics!B7 ) -> -0.00079431385
A3: w2 | B3: 0
A4: w3 | B4: =1-B2-B3 -> 1
A7: Return Matrix (rows = w2 Oracle, columns = w1 Microsoft)
A8: =G2 -> -0.00079431385 | B8: -0.3 | C8: -0.29 | D8: -0.28 | E8: -0.27 | F8: -0.26 | G8: -0.25 | H8: -0.24 | I8: -0.23 | J8: -0.22 | K8: -0.21 | L8: -0.2 | M8: -0.19 | N8: -0.18 | O8: -0.17 | P8: -0.16 | Q8: -0.15 | R8: -0.14 | S8: -0.13 | T8: -0.12 | U8: -0.11 | V8: -0.1 | W8: -0.09 | X8: -0.08 | Y8: -0.07 | Z8: -0.06 | AA8: -0.05 | AB8: -0.04 | AC8: -0.03 | AD8: -0.02 | AE8: -0.01 | AF8: 0 | AG8: 0.01 | AH8: 0.02 | AI8: 0.03 | AJ8: 0.04 | AK8: 0.05 | AL8: 0.06 | AM8: 0.07 | AN8: 0.08 | AO8: 0.09 | AP8: 0.1 | AQ8: 0.11 | AR8: 0.12 | AS8: 0.13 | AT8: 0.14 | AU8: 0.15 | AV8: 0.16 | AW8: 0.17 | AX8: 0.18 | AY8: 0.19 | AZ8: 0.2 | BA8: 0.21 | BB8: 0.22 | BC8: 0.23 | BD8: 0.24 | BE8: 0.25 | BF8: 0.26 | BG8: 0.27 | BH8: 0.28 | BI8: 0.29 | BJ8: 0.3
A9: -0.3 | B9: -0.0011949753 | C9: -0.0011881941 | D9: -0.001181413 | E9: -0.0011746318 | F9: -0.0011678506 | G9: -0.0011610694 | H9: -0.0011542883 | I9: -0.0011475071 | J9: -0.0011407259 | K9: -0.0011339447 | L9: -0.0011271636 | M9: -0.0011203824 | N9: -0.0011136012 | O9: -0.00110682 | P9: -0.0011000389 | Q9: -0.0010932577 | R9: -0.0010864765 | S9: -0.0010796953 | T9: -0.0010729142 | U9: -0.001066133 | V9: -0.0010593518 | W9: -0.0010525707 | X9: -0.0010457895 | Y9: -0.0010390083 | Z9: -0.0010322271 | AA9: -0.001025446 | AB9: -0.0010186648 | AC9: -0.0010118836 | AD9: -0.0010051024 | AE9: -0.00099832126 | AF9: -0.00099154009 | AG9: -0.00098475891 | AH9: -0.00097797774 | AI9: -0.00097119656 | AJ9: -0.00096441539 | AK9: -0.00095763422 | AL9: -0.00095085304 | AM9: -0.00094407187 | AN9: -0.00093729069 | AO9: -0.00093050952 | AP9: -0.00092372835 | AQ9: -0.00091694717 | AR9: -0.000910166 | AS9: -0.00090338482 | AT9: -0.00089660365 | AU9: -0.00088982248 | AV9: -0.0008830413 | AW9: -0.00087626013 | AX9: -0.00086947895 | AY9: -0.00086269778 | AZ9: -0.00085591661 | BA9: -0.00084913543 | BB9: -0.00084235426 | BC9: -0.00083557308 | BD9: -0.00082879191 | BE9: -0.00082201074 | BF9: -0.00081522956 | BG9: -0.00080844839 | BH9: -0.00080166721 | BI9: -0.00079488604 | BJ9: -0.00078810487
A10: -0.29 | B10: -0.0011884011 | C10: -0.0011816199 | D10: -0.0011748387 | E10: -0.0011680576 | F10: -0.0011612764 | G10: -0.0011544952 | H10: -0.0011477141 | I10: -0.0011409329 | J10: -0.0011341517 | K10: -0.0011273705 | L10: -0.0011205894 | M10: -0.0011138082 | N10: -0.001107027 | O10: -0.0011002458 | P10: -0.0010934647 | Q10: -0.0010866835 | R10: -0.0010799023 | S10: -0.0010731211 | T10: -0.00106634 | U10: -0.0010595588 | V10: -0.0010527776 | W10: -0.0010459964 | X10: -0.0010392153 | Y10: -0.0010324341 | Z10: -0.0010256529 | AA10: -0.0010188717 | AB10: -0.0010120906 | AC10: -0.0010053094 | AD10: -0.00099852823 | AE10: -0.00099174705 | AF10: -0.00098496588 | AG10: -0.0009781847 | AH10: -0.00097140353 | AI10: -0.00096462236 | AJ10: -0.00095784118 | AK10: -0.00095106001 | AL10: -0.00094427883 | AM10: -0.00093749766 | AN10: -0.00093071649 | AO10: -0.00092393531 | AP10: -0.00091715414 | AQ10: -0.00091037296 | AR10: -0.00090359179 | AS10: -0.00089681062 | AT10: -0.00089002944 | AU10: -0.00088324827 | AV10: -0.00087646709 | AW10: -0.00086968592 | AX10: -0.00086290475 | AY10: -0.00085612357 | AZ10: -0.0008493424 | BA10: -0.00084256122 | BB10: -0.00083578005 | BC10: -0.00082899888 | BD10: -0.0008222177 | BE10: -0.00081543653 | BF10: -0.00080865535 | BG10: -0.00080187418 | BH10: -0.00079509301 | BI10: -0.00078831183 | BJ10: -0.00078153066
A11: -0.28 | B11: -0.0011818269 | C11: -0.0011750457 | D11: -0.0011682645 | E11: -0.0011614834 | F11: -0.0011547022 | G11: -0.001147921 | H11: -0.0011411398 | I11: -0.0011343587 | J11: -0.0011275775 | K11: -0.0011207963 | L11: -0.0011140151 | M11: -0.001107234 | N11: -0.0011004528 | O11: -0.0010936716 | P11: -0.0010868905 | Q11: -0.0010801093 | R11: -0.0010733281 | S11: -0.0010665469 | T11: -0.0010597658 | U11: -0.0010529846 | V11: -0.0010462034 | W11: -0.0010394222 | X11: -0.0010326411 | Y11: -0.0010258599 | Z11: -0.0010190787 | AA11: -0.0010122975 | AB11: -0.0010055164 | AC11: -0.00099873519 | AD11: -0.00099195402 | AE11: -0.00098517284 | AF11: -0.00097839167 | AG11: -0.0009716105 | AH11: -0.00096482932 | AI11: -0.00095804815 | AJ11: -0.00095126697 | AK11: -0.0009444858 | AL11: -0.00093770463 | AM11: -0.00093092345 | AN11: -0.00092414228 | AO11: -0.0009173611 | AP11: -0.00091057993 | AQ11: -0.00090379876 | AR11: -0.00089701758 | AS11: -0.00089023641 | AT11: -0.00088345523 | AU11: -0.00087667406 | AV11: -0.00086989289 | AW11: -0.00086311171 | AX11: -0.00085633054 | AY11: -0.00084954936 | AZ11: -0.00084276819 | BA11: -0.00083598702 | BB11: -0.00082920584 | BC11: -0.00082242467 | BD11: -0.00081564349 | BE11: -0.00080886232 | BF11: -0.00080208115 | BG11: -0.00079529997 | BH11: -0.0007885188 | BI11: -0.00078173762 | BJ11: -0.00077495645
A12: -0.27 | B12: -0.0011752527 | C12: -0.0011684715 | D12: -0.0011616903 | E12: -0.0011549092 | F12: -0.001148128 | G12: -0.0011413468 | H12: -0.0011345656 | I12: -0.0011277845 | J12: -0.0011210033 | K12: -0.0011142221 | L12: -0.0011074409 | M12: -0.0011006598 | N12: -0.0010938786 | O12: -0.0010870974 | P12: -0.0010803162 | Q12: -0.0010735351 | R12: -0.0010667539 | S12: -0.0010599727 | T12: -0.0010531915 | U12: -0.0010464104 | V12: -0.0010396292 | W12: -0.001032848 | X12: -0.0010260669 | Y12: -0.0010192857 | Z12: -0.0010125045 | AA12: -0.0010057233 | AB12: -0.00099894216 | AC12: -0.00099216098 | AD12: -0.00098537981 | AE12: -0.00097859864 | AF12: -0.00097181746 | AG12: -0.00096503629 | AH12: -0.00095825511 | AI12: -0.00095147394 | AJ12: -0.00094469277 | AK12: -0.00093791159 | AL12: -0.00093113042 | AM12: -0.00092434924 | AN12: -0.00091756807 | AO12: -0.0009107869 | AP12: -0.00090400572 | AQ12: -0.00089722455 | AR12: -0.00089044337 | AS12: -0.0008836622 | AT12: -0.00087688103 | AU12: -0.00087009985 | AV12: -0.00086331868 | AW12: -0.0008565375 | AX12: -0.00084975633 | AY12: -0.00084297516 | AZ12: -0.00083619398 | BA12: -0.00082941281 | BB12: -0.00082263163 | BC12: -0.00081585046 | BD12: -0.00080906929 | BE12: -0.00080228811 | BF12: -0.00079550694 | BG12: -0.00078872576 | BH12: -0.00078194459 | BI12: -0.00077516342 | BJ12: -0.00076838224
A13: -0.26 | B13: -0.0011686785 | C13: -0.0011618973 | D13: -0.0011551161 | E13: -0.001148335 | F13: -0.0011415538 | G13: -0.0011347726 | H13: -0.0011279914 | I13: -0.0011212103 | J13: -0.0011144291 | K13: -0.0011076479 | L13: -0.0011008667 | M13: -0.0010940856 | N13: -0.0010873044 | O13: -0.0010805232 | P13: -0.001073742 | Q13: -0.0010669609 | R13: -0.0010601797 | S13: -0.0010533985 | T13: -0.0010466173 | U13: -0.0010398362 | V13: -0.001033055 | W13: -0.0010262738 | X13: -0.0010194926 | Y13: -0.0010127115 | Z13: -0.0010059303 | AA13: -0.00099914912 | AB13: -0.00099236795 | AC13: -0.00098558678 | AD13: -0.0009788056 | AE13: -0.00097202443 | AF13: -0.00096524325 | AG13: -0.00095846208 | AH13: -0.00095168091 | AI13: -0.00094489973 | AJ13: -0.00093811856 | AK13: -0.00093133738 | AL13: -0.00092455621 | AM13: -0.00091777504 | AN13: -0.00091099386 | AO13: -0.00090421269 | AP13: -0.00089743151 | AQ13: -0.00089065034 | AR13: -0.00088386917 | AS13: -0.00087708799 | AT13: -0.00087030682 | AU13: -0.00086352564 | AV13: -0.00085674447 | AW13: -0.0008499633 | AX13: -0.00084318212 | AY13: -0.00083640095 | AZ13: -0.00082961977 | BA13: -0.0008228386 | BB13: -0.00081605743 | BC13: -0.00080927625 | BD13: -0.00080249508 | BE13: -0.00079571391 | BF13: -0.00078893273 | BG13: -0.00078215156 | BH13: -0.00077537038 | BI13: -0.00076858921 | BJ13: -0.00076180804
A14: -0.25 | B14: -0.0011621043 | C14: -0.0011553231 | D14: -0.0011485419 | E14: -0.0011417607 | F14: -0.0011349796 | G14: -0.0011281984 | H14: -0.0011214172 | I14: -0.001114636 | J14: -0.0011078549 | K14: -0.0011010737 | L14: -0.0010942925 | M14: -0.0010875114 | N14: -0.0010807302 | O14: -0.001073949 | P14: -0.0010671678 | Q14: -0.0010603867 | R14: -0.0010536055 | S14: -0.0010468243 | T14: -0.0010400431 | U14: -0.001033262 | V14: -0.0010264808 | W14: -0.0010196996 | X14: -0.0010129184 | Y14: -0.0010061373 | Z14: -0.00099935609 | AA14: -0.00099257492 | AB14: -0.00098579374 | AC14: -0.00097901257 | AD14: -0.00097223139 | AE14: -0.00096545022 | AF14: -0.00095866905 | AG14: -0.00095188787 | AH14: -0.0009451067 | AI14: -0.00093832552 | AJ14: -0.00093154435 | AK14: -0.00092476318 | AL14: -0.000917982 | AM14: -0.00091120083 | AN14: -0.00090441965 | AO14: -0.00089763848 | AP14: -0.00089085731 | AQ14: -0.00088407613 | AR14: -0.00087729496 | AS14: -0.00087051378 | AT14: -0.00086373261 | AU14: -0.00085695144 | AV14: -0.00085017026 | AW14: -0.00084338909 | AX14: -0.00083660791 | AY14: -0.00082982674 | AZ14: -0.00082304557 | BA14: -0.00081626439 | BB14: -0.00080948322 | BC14: -0.00080270205 | BD14: -0.00079592087 | BE14: -0.0007891397 | BF14: -0.00078235852 | BG14: -0.00077557735 | BH14: -0.00076879618 | BI14: -0.000762015 | BJ14: -0.00075523383
A15: -0.24 | B15: -0.0011555301 | C15: -0.0011487489 | D15: -0.0011419677 | E15: -0.0011351865 | F15: -0.0011284054 | G15: -0.0011216242 | H15: -0.001114843 | I15: -0.0011080618 | J15: -0.0011012807 | K15: -0.0010944995 | L15: -0.0010877183 | M15: -0.0010809371 | N15: -0.001074156 | O15: -0.0010673748 | P15: -0.0010605936 | Q15: -0.0010538124 | R15: -0.0010470313 | S15: -0.0010402501 | T15: -0.0010334689 | U15: -0.0010266878 | V15: -0.0010199066 | W15: -0.0010131254 | X15: -0.0010063442 | Y15: -0.00099956306 | Z15: -0.00099278188 | AA15: -0.00098600071 | AB15: -0.00097921953 | AC15: -0.00097243836 | AD15: -0.00096565719 | AE15: -0.00095887601 | AF15: -0.00095209484 | AG15: -0.00094531366 | AH15: -0.00093853249 | AI15: -0.00093175132 | AJ15: -0.00092497014 | AK15: -0.00091818897 | AL15: -0.00091140779 | AM15: -0.00090462662 | AN15: -0.00089784545 | AO15: -0.00089106427 | AP15: -0.0008842831 | AQ15: -0.00087750192 | AR15: -0.00087072075 | AS15: -0.00086393958 | AT15: -0.0008571584 | AU15: -0.00085037723 | AV15: -0.00084359606 | AW15: -0.00083681488 | AX15: -0.00083003371 | AY15: -0.00082325253 | AZ15: -0.00081647136 | BA15: -0.00080969019 | BB15: -0.00080290901 | BC15: -0.00079612784 | BD15: -0.00078934666 | BE15: -0.00078256549 | BF15: -0.00077578432 | BG15: -0.00076900314 | BH15: -0.00076222197 | BI15: -0.00075544079 | BJ15: -0.00074865962
A16: -0.23 | B16: -0.0011489558 | C16: -0.0011421747 | D16: -0.0011353935 | E16: -0.0011286123 | F16: -0.0011218312 | G16: -0.00111505 | H16: -0.0011082688 | I16: -0.0011014876 | J16: -0.0010947065 | K16: -0.0010879253 | L16: -0.0010811441 | M16: -0.0010743629 | N16: -0.0010675818 | O16: -0.0010608006 | P16: -0.0010540194 | Q16: -0.0010472382 | R16: -0.0010404571 | S16: -0.0010336759 | T16: -0.0010268947 | U16: -0.0010201135 | V16: -0.0010133324 | W16: -0.0010065512 | X16: -0.00099977002 | Y16: -0.00099298885 | Z16: -0.00098620767 | AA16: -0.0009794265 | AB16: -0.00097264533 | AC16: -0.00096586415 | AD16: -0.00095908298 | AE16: -0.0009523018 | AF16: -0.00094552063 | AG16: -0.00093873946 | AH16: -0.00093195828 | AI16: -0.00092517711 | AJ16: -0.00091839593 | AK16: -0.00091161476 | AL16: -0.00090483359 | AM16: -0.00089805241 | AN16: -0.00089127124 | AO16: -0.00088449007 | AP16: -0.00087770889 | AQ16: -0.00087092772 | AR16: -0.00086414654 | AS16: -0.00085736537 | AT16: -0.0008505842 | AU16: -0.00084380302 | AV16: -0.00083702185 | AW16: -0.00083024067 | AX16: -0.0008234595 | AY16: -0.00081667833 | AZ16: -0.00080989715 | BA16: -0.00080311598 | BB16: -0.0007963348 | BC16: -0.00078955363 | BD16: -0.00078277246 | BE16: -0.00077599128 | BF16: -0.00076921011 | BG16: -0.00076242893 | BH16: -0.00075564776 | BI16: -0.00074886659 | BJ16: -0.00074208541
A17: -0.22 | B17: -0.0011423816 | C17: -0.0011356005 | D17: -0.0011288193 | E17: -0.0011220381 | F17: -0.0011152569 | G17: -0.0011084758 | H17: -0.0011016946 | I17: -0.0010949134 | J17: -0.0010881323 | K17: -0.0010813511 | L17: -0.0010745699 | M17: -0.0010677887 | N17: -0.0010610076 | O17: -0.0010542264 | P17: -0.0010474452 | Q17: -0.001040664 | R17: -0.0010338829 | S17: -0.0010271017 | T17: -0.0010203205 | U17: -0.0010135393 | V17: -0.0010067582 | W17: -0.00099997699 | X17: -0.00099319581 | Y17: -0.00098641464 | Z17: -0.00097963347 | AA17: -0.00097285229 | AB17: -0.00096607112 | AC17: -0.00095928994 | AD17: -0.00095250877 | AE17: -0.0009457276 | AF17: -0.00093894642 | AG17: -0.00093216525 | AH17: -0.00092538407 | AI17: -0.0009186029 | AJ17: -0.00091182173 | AK17: -0.00090504055 | AL17: -0.00089825938 | AM17: -0.00089147821 | AN17: -0.00088469703 | AO17: -0.00087791586 | AP17: -0.00087113468 | AQ17: -0.00086435351 | AR17: -0.00085757234 | AS17: -0.00085079116 | AT17: -0.00084400999 | AU17: -0.00083722881 | AV17: -0.00083044764 | AW17: -0.00082366647 | AX17: -0.00081688529 | AY17: -0.00081010412 | AZ17: -0.00080332294 | BA17: -0.00079654177 | BB17: -0.0007897606 | BC17: -0.00078297942 | BD17: -0.00077619825 | BE17: -0.00076941707 | BF17: -0.0007626359 | BG17: -0.00075585473 | BH17: -0.00074907355 | BI17: -0.00074229238 | BJ17: -0.0007355112
A18: -0.21 | B18: -0.0011358074 | C18: -0.0011290263 | D18: -0.0011222451 | E18: -0.0011154639 | F18: -0.0011086827 | G18: -0.0011019016 | H18: -0.0010951204 | I18: -0.0010883392 | J18: -0.001081558 | K18: -0.0010747769 | L18: -0.0010679957 | M18: -0.0010612145 | N18: -0.0010544333 | O18: -0.0010476522 | P18: -0.001040871 | Q18: -0.0010340898 | R18: -0.0010273087 | S18: -0.0010205275 | T18: -0.0010137463 | U18: -0.0010069651 | V18: -0.001000184 | W18: -0.00099340278 | X18: -0.00098662161 | Y18: -0.00097984043 | Z18: -0.00097305926 | AA18: -0.00096627808 | AB18: -0.00095949691 | AC18: -0.00095271574 | AD18: -0.00094593456 | AE18: -0.00093915339 | AF18: -0.00093237222 | AG18: -0.00092559104 | AH18: -0.00091880987 | AI18: -0.00091202869 | AJ18: -0.00090524752 | AK18: -0.00089846635 | AL18: -0.00089168517 | AM18: -0.000884904 | AN18: -0.00087812282 | AO18: -0.00087134165 | AP18: -0.00086456048 | AQ18: -0.0008577793 | AR18: -0.00085099813 | AS18: -0.00084421695 | AT18: -0.00083743578 | AU18: -0.00083065461 | AV18: -0.00082387343 | AW18: -0.00081709226 | AX18: -0.00081031108 | AY18: -0.00080352991 | AZ18: -0.00079674874 | BA18: -0.00078996756 | BB18: -0.00078318639 | BC18: -0.00077640521 | BD18: -0.00076962404 | BE18: -0.00076284287 | BF18: -0.00075606169 | BG18: -0.00074928052 | BH18: -0.00074249934 | BI18: -0.00073571817 | BJ18: -0.000728937
A19: -0.2 | B19: -0.0011292332 | C19: -0.0011224521 | D19: -0.0011156709 | E19: -0.0011088897 | F19: -0.0011021085 | G19: -0.0010953274 | H19: -0.0010885462 | I19: -0.001081765 | J19: -0.0010749838 | K19: -0.0010682027 | L19: -0.0010614215 | M19: -0.0010546403 | N19: -0.0010478591 | O19: -0.001041078 | P19: -0.0010342968 | Q19: -0.0010275156 | R19: -0.0010207344 | S19: -0.0010139533 | T19: -0.0010071721 | U19: -0.0010003909 | V19: -0.00099360975 | W19: -0.00098682857 | X19: -0.0009800474 | Y19: -0.00097326622 | Z19: -0.00096648505 | AA19: -0.00095970388 | AB19: -0.0009529227 | AC19: -0.00094614153 | AD19: -0.00093936036 | AE19: -0.00093257918 | AF19: -0.00092579801 | AG19: -0.00091901683 | AH19: -0.00091223566 | AI19: -0.00090545449 | AJ19: -0.00089867331 | AK19: -0.00089189214 | AL19: -0.00088511096 | AM19: -0.00087832979 | AN19: -0.00087154862 | AO19: -0.00086476744 | AP19: -0.00085798627 | AQ19: -0.00085120509 | AR19: -0.00084442392 | AS19: -0.00083764275 | AT19: -0.00083086157 | AU19: -0.0008240804 | AV19: -0.00081729922 | AW19: -0.00081051805 | AX19: -0.00080373688 | AY19: -0.0007969557 | AZ19: -0.00079017453 | BA19: -0.00078339335 | BB19: -0.00077661218 | BC19: -0.00076983101 | BD19: -0.00076304983 | BE19: -0.00075626866 | BF19: -0.00074948748 | BG19: -0.00074270631 | BH19: -0.00073592514 | BI19: -0.00072914396 | BJ19: -0.00072236279
A20: -0.19 | B20: -0.001122659 | C20: -0.0011158778 | D20: -0.0011090967 | E20: -0.0011023155 | F20: -0.0010955343 | G20: -0.0010887531 | H20: -0.001081972 | I20: -0.0010751908 | J20: -0.0010684096 | K20: -0.0010616285 | L20: -0.0010548473 | M20: -0.0010480661 | N20: -0.0010412849 | O20: -0.0010345038 | P20: -0.0010277226 | Q20: -0.0010209414 | R20: -0.0010141602 | S20: -0.0010073791 | T20: -0.0010005979 | U20: -0.00099381671 | V20: -0.00098703554 | W20: -0.00098025437 | X20: -0.00097347319 | Y20: -0.00096669202 | Z20: -0.00095991084 | AA20: -0.00095312967 | AB20: -0.0009463485 | AC20: -0.00093956732 | AD20: -0.00093278615 | AE20: -0.00092600497 | AF20: -0.0009192238 | AG20: -0.00091244263 | AH20: -0.00090566145 | AI20: -0.00089888028 | AJ20: -0.0008920991 | AK20: -0.00088531793 | AL20: -0.00087853676 | AM20: -0.00087175558 | AN20: -0.00086497441 | AO20: -0.00085819323 | AP20: -0.00085141206 | AQ20: -0.00084463089 | AR20: -0.00083784971 | AS20: -0.00083106854 | AT20: -0.00082428736 | AU20: -0.00081750619 | AV20: -0.00081072502 | AW20: -0.00080394384 | AX20: -0.00079716267 | AY20: -0.00079038149 | AZ20: -0.00078360032 | BA20: -0.00077681915 | BB20: -0.00077003797 | BC20: -0.0007632568 | BD20: -0.00075647562 | BE20: -0.00074969445 | BF20: -0.00074291328 | BG20: -0.0007361321 | BH20: -0.00072935093 | BI20: -0.00072256975 | BJ20: -0.00071578858
... A69: 0.3 | B69: -0.00080052283 | C69: -0.00079374166 | D69: -0.00078696049 | E69: -0.00078017931 | F69: -0.00077339814 | G69: -0.00076661696 | H69: -0.00075983579 | I69: -0.00075305462 | J69: -0.00074627344 | K69: -0.00073949227 | L69: -0.00073271109 | M69: -0.00072592992 | N69: -0.00071914875 | O69: -0.00071236757 | P69: -0.0007055864 | Q69: -0.00069880522 | R69: -0.00069202405 | S69: -0.00068524288 | T69: -0.0006784617 | U69: -0.00067168053 | V69: -0.00066489935 | W69: -0.00065811818 | X69: -0.00065133701 | Y69: -0.00064455583 | Z69: -0.00063777466 | AA69: -0.00063099348 | AB69: -0.00062421231 | AC69: -0.00061743114 | AD69: -0.00061064996 | AE69: -0.00060386879 | AF69: -0.00059708761 | AG69: -0.00059030644 | AH69: -0.00058352527 | AI69: -0.00057674409 | AJ69: -0.00056996292 | AK69: -0.00056318175 | AL69: -0.00055640057 | AM69: -0.0005496194 | AN69: -0.00054283822 | AO69: -0.00053605705 | AP69: -0.00052927588 | AQ69: -0.0005224947 | AR69: -0.00051571353 | AS69: -0.00050893235 | AT69: -0.00050215118 | AU69: -0.00049537001 | AV69: -0.00048858883 | AW69: -0.00048180766 | AX69: -0.00047502648 | AY69: -0.00046824531 | AZ69: -0.00046146414 | BA69: -0.00045468296 | BB69: -0.00044790179 | BC69: -0.00044112061 | BD69: -0.00043433944 | BE69: -0.00042755827 | BF69: -0.00042077709 | BG69: -0.00041399592 | BH69: -0.00040721474 | BI69: -0.00040043357 | BJ69: -0.0003936524

Sheet Portfolio Weights Std
A1: Weights | Q1: Covariance Matrix
A2: w1 | B2: 0 | D2: Standard Deviation of portfolio | G2: =(( B2^2 *R4) + (B3^2*S5) + (B4^2*T6) + (2*B2*B3*S4) + (2*B2*B4*T4) + (2*B3*B4*T5))^(1/2) -> 0.019138596
A3: w2 | B3: 0 | Q3: Column1 | R3: Microsoft | S3: Oracle | T3: Sony
A4: w3 | B4: =1-B2-B3 -> 1 | Q4: Microsoft | R4: =_xlfn.COVARIANCE.S(Returns!B3:B251,Returns!B3:B251) -> 0.00027529141 | S4: =_xlfn.COVARIANCE.S(Returns!B3:B251,Returns!C3:C251) -> 0.00024862063 | T4: =_xlfn.COVARIANCE.S(Returns!B3:B251,Returns!D3:D251) -> 8.9273997e-05
Q5: Oracle | R5: =_xlfn.COVARIANCE.S(Returns!S19:S267,Returns!R19:R267) -> #DIV/0! | S5: =_xlfn.COVARIANCE.S(Returns!C3:C251,Returns!C3:C251) -> 0.0013686392 | T5: =_xlfn.COVARIANCE.S(Returns!C3:C251,Returns!D3:D251) -> 0.00014468916
Q6: Sony | R6: =_xlfn.COVARIANCE.S(Returns!T19:T267,Returns!R19:R267) -> #DIV/0! | S6: =_xlfn.COVARIANCE.S(Returns!T19:T267,Returns!S19:S267) -> #DIV/0! | T6: =_xlfn.COVARIANCE.S(Returns!D3:D251,Returns!D3:D251) -> 0.00036628586
A8: =G2 -> 0.019138596 | B8: -0.3 | C8: -0.29 | D8: -0.28 | E8: -0.27 | F8: -0.26 | G8: -0.25 | H8: -0.24 | I8: -0.23 | J8: -0.22 | K8: -0.21 | L8: -0.2 | M8: -0.19 | N8: -0.18 | O8: -0.17 | P8: -0.16 | Q8: -0.15 | R8: -0.14 | S8: -0.13 | T8: -0.12 | U8: -0.11 | V8: -0.1 | W8: -0.09 | X8: -0.08 | Y8: -0.07 | Z8: -0.06 | AA8: -0.05 | AB8: -0.04 | AC8: -0.03 | AD8: -0.02 | AE8: -0.01 | AF8: 0 | AG8: 0.01 | AH8: 0.02 | AI8: 0.03 | AJ8: 0.04 | AK8: 0.05 | AL8: 0.06 | AM8: 0.07 | AN8: 0.08 | AO8: 0.09 | AP8: 0.1 | AQ8: 0.11 | AR8: 0.12 | AS8: 0.13 | AT8: 0.14 | AU8: 0.15 | AV8: 0.16 | AW8: 0.17 | AX8: 0.18 | AY8: 0.19 | AZ8: 0.2 | BA8: 0.21 | BB8: 0.22 | BC8: 0.23 | BD8: 0.24 | BE8: 0.25 | BF8: 0.26 | BG8: 0.27 | BH8: 0.28 | BI8: 0.29 | BJ8: 0.3
A9: -0.3 | B9: 0.030096389 | C9: 0.029920476 | D9: 0.029745079 | E9: 0.029570207 | F9: 0.029395871 | G9: 0.029222078 | H9: 0.02904884 | I9: 0.028876166 | J9: 0.028704067 | K9: 0.028532552 | L9: 0.028361633 | M9: 0.02819132 | N9: 0.028021624 | O9: 0.027852556 | P9: 0.027684129 | Q9: 0.027516354 | R9: 0.027349242 | S9: 0.027182806 | T9: 0.027017059 | U9: 0.026852013 | V9: 0.026687682 | W9: 0.026524078 | X9: 0.026361215 | Y9: 0.026199107 | Z9: 0.026037768 | AA9: 0.025877213 | AB9: 0.025717456 | AC9: 0.025558512 | AD9: 0.025400396 | AE9: 0.025243124 | AF9: 0.025086712 | AG9: 0.024931175 | AH9: 0.024776531 | AI9: 0.024622797 | AJ9: 0.024469989 | AK9: 0.024318125 | AL9: 0.024167222 | AM9: 0.024017299 | AN9: 0.023868375 | AO9: 0.023720467 | AP9: 0.023573596 | AQ9: 0.02342778 | AR9: 0.02328304 | AS9: 0.023139396 | AT9: 0.022996867 | AU9: 0.022855476 | AV9: 0.022715244 | AW9: 0.022576191 | AX9: 0.02243834 | AY9: 0.022301713 | AZ9: 0.022166333 | BA9: 0.022032223 | BB9: 0.021899406 | BC9: 0.021767905 | BD9: 0.021637746 | BE9: 0.021508951 | BF9: 0.021381547 | BG9: 0.021255557 | BH9: 0.021131007 | BI9: 0.021007923 | BJ9: 0.020886331
A10: -0.29 | B10: 0.029842023 | C10: 0.029665885 | D10: 0.029490266 | E10: 0.029315174 | F10: 0.029140618 | G10: 0.02896661 | H10: 0.028793158 | I10: 0.028620272 | J10: 0.028447964 | K10: 0.028276243 | L10: 0.02810512 | M10: 0.027934607 | N10: 0.027764714 | O10: 0.027595453 | P10: 0.027426836 | Q10: 0.027258874 | R10: 0.02709158 | S10: 0.026924967 | T10: 0.026759046 | U10: 0.026593832 | V10: 0.026429336 | W10: 0.026265573 | X10: 0.026102557 | Y10: 0.025940301 | Z10: 0.025778821 | AA10: 0.025618129 | AB10: 0.025458243 | AC10: 0.025299176 | AD10: 0.025140944 | AE10: 0.024983564 | AF10: 0.02482705 | AG10: 0.024671421 | AH10: 0.024516693 | AI10: 0.024362882 | AJ10: 0.024210007 | AK10: 0.024058085 | AL10: 0.023907135 | AM10: 0.023757174 | AN10: 0.023608222 | AO10: 0.023460298 | AP10: 0.023313422 | AQ10: 0.023167613 | AR10: 0.023022892 | AS10: 0.022879279 | AT10: 0.022736796 | AU10: 0.022595463 | AV10: 0.022455303 | AW10: 0.022316338 | AX10: 0.022178589 | AY10: 0.022042081 | AZ10: 0.021906835 | BA10: 0.021772876 | BB10: 0.021640228 | BC10: 0.021508914 | BD10: 0.02137896 | BE10: 0.021250389 | BF10: 0.021123229 | BG10: 0.020997503 | BH10: 0.020873239 | BI10: 0.020750461 | BJ10: 0.020629198
A11: -0.28 | B11: 0.029590355 | C11: 0.029414006 | D11: 0.029238176 | E11: 0.029062876 | F11: 0.028888115 | G11: 0.028713903 | H11: 0.02854025 | I11: 0.028367166 | J11: 0.028194662 | K11: 0.028022748 | L11: 0.027851435 | M11: 0.027680736 | N11: 0.02751066 | O11: 0.027341219 | P11: 0.027172426 | Q11: 0.027004293 | R11: 0.026836832 | S11: 0.026670055 | T11: 0.026503976 | U11: 0.026338608 | V11: 0.026173964 | W11: 0.026010058 | X11: 0.025846904 | Y11: 0.025684516 | Z11: 0.02552291 | AA11: 0.025362099 | AB11: 0.025202099 | AC11: 0.025042927 | AD11: 0.024884596 | AE11: 0.024727125 | AF11: 0.024570529 | AG11: 0.024414825 | AH11: 0.02426003 | AI11: 0.024106162 | AJ11: 0.023953239 | AK11: 0.023801279 | AL11: 0.0236503 | AM11: 0.023500321 | AN11: 0.023351362 | AO11: 0.023203442 | AP11: 0.023056582 | AQ11: 0.022910801 | AR11: 0.022766121 | AS11: 0.022622562 | AT11: 0.022480146 | AU11: 0.022338895 | AV11: 0.022198831 | AW11: 0.022059977 | AX11: 0.021922356 | AY11: 0.02178599 | AZ11: 0.021650904 | BA11: 0.021517122 | BB11: 0.021384669 | BC11: 0.021253568 | BD11: 0.021123847 | BE11: 0.020995528 | BF11: 0.02086864 | BG11: 0.020743208 | BH11: 0.020619258 | BI11: 0.020496818 | BJ11: 0.020375915
A12: -0.27 | B12: 0.029341456 | C12: 0.029164907 | D12: 0.028988881 | E12: 0.028813386 | F12: 0.028638433 | G12: 0.028464031 | H12: 0.028290191 | I12: 0.028116922 | J12: 0.027944236 | K12: 0.027772144 | L12: 0.027600657 | M12: 0.027429785 | N12: 0.027259541 | O12: 0.027089936 | P12: 0.026920982 | Q12: 0.026752693 | R12: 0.02658508 | S12: 0.026418156 | T12: 0.026251934 | U12: 0.026086428 | V12: 0.025921652 | W12: 0.02575762 | X12: 0.025594345 | Y12: 0.025431842 | Z12: 0.025270127 | AA12: 0.025109215 | AB12: 0.024949121 | AC12: 0.02478986 | AD12: 0.02463145 | AE12: 0.024473906 | AF12: 0.024317246 | AG12: 0.024161486 | AH12: 0.024006645 | AI12: 0.023852739 | AJ12: 0.023699788 | AK12: 0.02354781 | AL12: 0.023396824 | AM12: 0.023246849 | AN12: 0.023097904 | AO12: 0.022950011 | AP12: 0.022803189 | AQ12: 0.022657459 | AR12: 0.022512843 | AS12: 0.022369361 | AT12: 0.022227037 | AU12: 0.022085892 | AV12: 0.021945949 | AW12: 0.021807232 | AX12: 0.021669763 | AY12: 0.021533567 | AZ12: 0.021398668 | BA12: 0.021265091 | BB12: 0.02113286 | BC12: 0.021002002 | BD12: 0.020872541 | BE12: 0.020744505 | BF12: 0.02061792 | BG12: 0.020492812 | BH12: 0.020369209 | BI12: 0.020247138 | BJ12: 0.020126628
A13: -0.26 | B13: 0.029095395 | C13: 0.028918662 | D13: 0.028742453 | E13: 0.028566778 | F13: 0.028391647 | G13: 0.028217069 | H13: 0.028043057 | I13: 0.027869619 | J13: 0.027696766 | K13: 0.027524511 | L13: 0.027352863 | M13: 0.027181835 | N13: 0.027011439 | O13: 0.026841686 | P13: 0.026672588 | Q13: 0.026504158 | R13: 0.02633641 | S13: 0.026169355 | T13: 0.026003008 | U13: 0.025837383 | V13: 0.025672492 | W13: 0.02550835 | X13: 0.025344973 | Y13: 0.025182374 | Z13: 0.025020569 | AA13: 0.024859574 | AB13: 0.024699403 | AC13: 0.024540075 | AD13: 0.024381604 | AE13: 0.024224008 | AF13: 0.024067304 | AG13: 0.023911509 | AH13: 0.023756642 | AI13: 0.02360272 | AJ13: 0.023449763 | AK13: 0.023297789 | AL13: 0.023146818 | AM13: 0.022996868 | AN13: 0.022847962 | AO13: 0.022700118 | AP13: 0.022553358 | AQ13: 0.022407704 | AR13: 0.022263176 | AS13: 0.022119798 | AT13: 0.021977591 | AU13: 0.021836578 | AV13: 0.021696783 | AW13: 0.021558229 | AX13: 0.021420941 | AY13: 0.021284942 | AZ13: 0.021150258 | BA13: 0.021016915 | BB13: 0.020884937 | BC13: 0.020754351 | BD13: 0.020625183 | BE13: 0.02049746 | BF13: 0.02037121 | BG13: 0.020246459 | BH13: 0.020123236 | BI13: 0.020001568 | BJ13: 0.019881486
A14: -0.25 | B14: 0.028852247 | C14: 0.028675343 | D14: 0.028498967 | E14: 0.028323126 | F14: 0.028147832 | G14: 0.027973095 | H14: 0.027798926 | I14: 0.027625334 | J14: 0.027452331 | K14: 0.027279929 | L14: 0.027108138 | M14: 0.02693697 | N14: 0.026766438 | O14: 0.026596553 | P14: 0.026427329 | Q14: 0.026258777 | R14: 0.026090911 | S14: 0.025923744 | T14: 0.025757289 | U14: 0.025591562 | V14: 0.025426575 | W14: 0.025262344 | X14: 0.025098883 | Y14: 0.024936207 | Z14: 0.024774332 | AA14: 0.024613274 | AB14: 0.024453048 | AC14: 0.024293672 | AD14: 0.024135161 | AE14: 0.023977534 | AF14: 0.023820808 | AG14: 0.023665 | AH14: 0.02351013 | AI14: 0.023356214 | AJ14: 0.023203274 | AK14: 0.023051327 | AL14: 0.022900395 | AM14: 0.022750496 | AN14: 0.022601651 | AO14: 0.022453883 | AP14: 0.022307211 | AQ14: 0.022161657 | AR14: 0.022017245 | AS14: 0.021873996 | AT14: 0.021731933 | AU14: 0.02159108 | AV14: 0.021451461 | AW14: 0.0213131 | AX14: 0.021176021 | AY14: 0.02104025 | AZ14: 0.020905812 | BA14: 0.020772733 | BB14: 0.02064104 | BC14: 0.020510758 | BD14: 0.020381916 | BE14: 0.020254539 | BF14: 0.020128658 | BG14: 0.020004299 | BH14: 0.019881491 | BI14: 0.019760263 | BJ14: 0.019640644
A15: -0.24 | B15: 0.028612084 | C15: 0.028435027 | D15: 0.028258498 | E15: 0.028082508 | F15: 0.027907068 | G15: 0.027732188 | H15: 0.027557878 | I15: 0.027384149 | J15: 0.027211013 | K15: 0.027038481 | L15: 0.026866564 | M15: 0.026695274 | N15: 0.026524624 | O15: 0.026354626 | P15: 0.026185293 | Q15: 0.026016637 | R15: 0.025848672 | S15: 0.025681412 | T15: 0.02551487 | U15: 0.02534906 | V15: 0.025183997 | W15: 0.025019696 | X15: 0.024856172 | Y15: 0.02469344 | Z15: 0.024531516 | AA15: 0.024370416 | AB15: 0.024210157 | AC15: 0.024050755 | AD15: 0.023892227 | AE15: 0.023734592 | AF15: 0.023577866 | AG15: 0.023422069 | AH15: 0.023267219 | AI15: 0.023113334 | AJ15: 0.022960435 | AK15: 0.022808541 | AL15: 0.022657672 | AM15: 0.022507849 | AN15: 0.022359093 | AO15: 0.022211426 | AP15: 0.022064868 | AQ15: 0.021919444 | AR15: 0.021775174 | AS15: 0.021632083 | AT15: 0.021490194 | AU15: 0.021349531 | AV15: 0.021210117 | AW15: 0.021071979 | AX15: 0.020935141 | AY15: 0.02079963 | AZ15: 0.02066547 | BA15: 0.020532688 | BB15: 0.020401313 | BC15: 0.02027137 | BD15: 0.020142887 | BE15: 0.020015893 | BF15: 0.019890416 | BG15: 0.019766485 | BH15: 0.01964413 | BI15: 0.019523379 | BJ15: 0.019404264
A16: -0.23 | B16: 0.028374984 | C16: 0.028197788 | D16: 0.028021124 | E16: 0.027845003 | F16: 0.027669433 | G16: 0.027494427 | H16: 0.027319995 | I16: 0.027146147 | J16: 0.026972895 | K16: 0.026800251 | L16: 0.026628227 | M16: 0.026456834 | N16: 0.026286086 | O16: 0.026115994 | P16: 0.025946571 | Q16: 0.025777831 | R16: 0.025609788 | S16: 0.025442454 | T16: 0.025275844 | U16: 0.025109974 | V16: 0.024944856 | W16: 0.024780506 | X16: 0.024616941 | Y16: 0.024454175 | Z16: 0.024292224 | AA16: 0.024131105 | AB16: 0.023970835 | AC16: 0.023811431 | AD16: 0.02365291 | AE16: 0.02349529 | AF16: 0.02333859 | AG16: 0.023182828 | AH16: 0.023028023 | AI16: 0.022874194 | AJ16: 0.022721362 | AK16: 0.022569547 | AL16: 0.022418769 | AM16: 0.02226905 | AN16: 0.02212041 | AO16: 0.021972872 | AP16: 0.021826459 | AQ16: 0.021681192 | AR16: 0.021537095 | AS16: 0.021394192 | AT16: 0.021252507 | AU16: 0.021112065 | AV16: 0.02097289 | AW16: 0.020835007 | AX16: 0.020698443 | AY16: 0.020563224 | AZ16: 0.020429376 | BA16: 0.020296927 | BB16: 0.020165904 | BC16: 0.020036336 | BD16: 0.01990825 | BE16: 0.019781675 | BF16: 0.019656642 | BG16: 0.019533178 | BH16: 0.019411314 | BI16: 0.019291081 | BJ16: 0.019172509
A17: -0.22 | B17: 0.028141023 | C17: 0.027963707 | D17: 0.027786926 | E17: 0.02761069 | F17: 0.027435009 | G17: 0.027259896 | H17: 0.027085359 | I17: 0.026911411 | J17: 0.026738063 | K17: 0.026565327 | L17: 0.026393215 | M17: 0.026221739 | N17: 0.026050912 | O17: 0.025880746 | P17: 0.025711255 | Q17: 0.025542452 | R17: 0.025374351 | S17: 0.025206966 | T17: 0.025040311 | U17: 0.024874401 | V17: 0.02470925 | W17: 0.024544875 | X17: 0.024381291 | Y17: 0.024218514 | Z17: 0.024056561 | AA17: 0.023895447 | AB17: 0.023735191 | AC17: 0.023575809 | AD17: 0.02341732 | AE17: 0.023259741 | AF17: 0.023103092 | AG17: 0.022947392 | AH17: 0.022792659 | AI17: 0.022638914 | AJ17: 0.022486177 | AK17: 0.022334469 | AL17: 0.022183811 | AM17: 0.022034223 | AN17: 0.02188573 | AO17: 0.021738351 | AP17: 0.021592112 | AQ17: 0.021447034 | AR17: 0.021303142 | AS17: 0.021160459 | AT17: 0.021019011 | AU17: 0.020878822 | AV17: 0.020739918 | AW17: 0.020602326 | AX17: 0.020466071 | AY17: 0.02033118 | AZ17: 0.02019768 | BA17: 0.0200656 | BB17: 0.019934968 | BC17: 0.019805812 | BD17: 0.019678162 | BE17: 0.019552046 | BF17: 0.019427495 | BG17: 0.019304539 | BH17: 0.019183209 | BI17: 0.019063536 | BJ17: 0.01894555
A18: -0.21 | B18: 0.02791028 | C18: 0.027732862 | D18: 0.027555982 | E18: 0.027379651 | F18: 0.027203879 | G18: 0.027028677 | H18: 0.026854057 | I18: 0.026680029 | J18: 0.026506605 | K18: 0.026333797 | L18: 0.026161618 | M18: 0.02599008 | N18: 0.025819195 | O18: 0.025648977 | P18: 0.025479439 | Q18: 0.025310595 | R18: 0.025142459 | S18: 0.024975045 | T18: 0.024808368 | U18: 0.024642442 | V18: 0.024477283 | W18: 0.024312907 | X18: 0.024149329 | Y18: 0.023986566 | Z18: 0.023824634 | AA18: 0.023663551 | AB18: 0.023503335 | AC18: 0.023344002 | AD18: 0.023185571 | AE18: 0.023028061 | AF18: 0.022871491 | AG18: 0.02271588 | AH18: 0.022561248 | AI18: 0.022407615 | AJ18: 0.022255003 | AK18: 0.022103431 | AL18: 0.021952922 | AM18: 0.021803498 | AN18: 0.021655181 | AO18: 0.021507995 | AP18: 0.021361961 | AQ18: 0.021217105 | AR18: 0.021073451 | AS18: 0.020931022 | AT18: 0.020789845 | AU18: 0.020649946 | AV18: 0.020511349 | AW18: 0.020374083 | AX18: 0.020238173 | AY18: 0.020103648 | AZ18: 0.019970535 | BA18: 0.019838863 | BB18: 0.019708661 | BC18: 0.019579958 | BD18: 0.019452784 | BE18: 0.019327168 | BF18: 0.019203143 | BG18: 0.019080738 | BH18: 0.018959984 | BI18: 0.018840915 | BJ18: 0.018723561
A19: -0.2 | B19: 0.027682835 | C19: 0.027505336 | D19: 0.027328377 | E19: 0.027151971 | F19: 0.026976128 | G19: 0.026800858 | H19: 0.026626174 | I19: 0.026452087 | J19: 0.026278609 | K19: 0.026105751 | L19: 0.025933527 | M19: 0.025761948 | N19: 0.025591029 | O19: 0.025420782 | P19: 0.025251221 | Q19: 0.025082359 | R19: 0.024914212 | S19: 0.024746793 | T19: 0.024580117 | U19: 0.024414201 | V19: 0.024249058 | W19: 0.024084706 | X19: 0.02392116 | Y19: 0.023758437 | Z19: 0.023596555 | AA19: 0.02343553 | AB19: 0.02327538 | AC19: 0.023116124 | AD19: 0.02295778 | AE19: 0.022800367 | AF19: 0.022643905 | AG19: 0.022488413 | AH19: 0.022333912 | AI19: 0.022180422 | AJ19: 0.022027965 | AK19: 0.021876561 | AL19: 0.021726234 | AM19: 0.021577006 | AN19: 0.021428899 | AO19: 0.021281937 | AP19: 0.021136144 | AQ19: 0.020991545 | AR19: 0.020848163 | AS19: 0.020706025 | AT19: 0.020565156 | AU19: 0.020425582 | AV19: 0.020287331 | AW19: 0.020150429 | AX19: 0.020014904 | AY19: 0.019880784 | AZ19: 0.019748098 | BA19: 0.019616875 | BB19: 0.019487144 | BC19: 0.019358936 | BD19: 0.019232281 | BE19: 0.01910721 | BF19: 0.018983754 | BG19: 0.018861945 | BH19: 0.018741815 | BI19: 0.018623396 | BJ19: 0.018506721
A20: -0.19 | B20: 0.027458772 | C20: 0.027281211 | D20: 0.027104195 | E20: 0.026927734 | F20: 0.026751841 | G20: 0.026576526 | H20: 0.0264018 | I20: 0.026227676 | J20: 0.026054166 | K20: 0.025881281 | L20: 0.025709035 | M20: 0.02553744 | N20: 0.025366509 | O20: 0.025196257 | P20: 0.025026697 | Q20: 0.024857843 | R20: 0.024689709 | S20: 0.024522311 | T20: 0.024355663 | U20: 0.024189782 | V20: 0.024024682 | W20: 0.023860381 | X20: 0.023696895 | Y20: 0.02353424 | Z20: 0.023372434 | AA20: 0.023211496 | AB20: 0.023051442 | AC20: 0.022892292 | AD20: 0.022734065 | AE20: 0.02257678 | AF20: 0.022420456 | AG20: 0.022265115 | AH20: 0.022110776 | AI20: 0.021957461 | AJ20: 0.021805192 | AK20: 0.021653991 | AL20: 0.021503879 | AM20: 0.021354881 | AN20: 0.021207019 | AO20: 0.021060318 | AP20: 0.020914802 | AQ20: 0.020770495 | AR20: 0.020627424 | AS20: 0.020485613 | AT20: 0.020345091 | AU20: 0.020205882 | AV20: 0.020068016 | AW20: 0.019931518 | AX20: 0.019796419 | AY20: 0.019662746 | AZ20: 0.019530529 | BA20: 0.019399798 | BB20: 0.019270583 | BC20: 0.019142915 | BD20: 0.019016824 | BE20: 0.018892343 | BF20: 0.018769503 | BG20: 0.018648337 | BH20: 0.018528878 | BI20: 0.018411159 | BJ20: 0.018295213
... A69: 0.3 | B69: 0.022421798 | C69: 0.022287902 | D69: 0.022155286 | E69: 0.022023975 | F69: 0.021893991 | G69: 0.021765358 | H69: 0.0216381 | I69: 0.021512243 | J69: 0.021387809 | K69: 0.021264825 | L69: 0.021143315 | M69: 0.021023306 | N69: 0.020904822 | O69: 0.020787891 | P69: 0.020672538 | Q69: 0.020558791 | R69: 0.020446675 | S69: 0.020336218 | T69: 0.020227447 | U69: 0.020120389 | V69: 0.020015072 | W69: 0.019911524 | X69: 0.019809772 | Y69: 0.019709844 | Z69: 0.019611767 | AA69: 0.019515571 | AB69: 0.019421282 | AC69: 0.019328929 | AD69: 0.01923854 | AE69: 0.019150142 | AF69: 0.019063763 | AG69: 0.01897943 | AH69: 0.018897172 | AI69: 0.018817015 | AJ69: 0.018738986 | AK69: 0.018663112 | AL69: 0.018589419 | AM69: 0.018517933 | AN69: 0.018448681 | AO69: 0.018381686 | AP69: 0.018316975 | AQ69: 0.018254571 | AR69: 0.018194498 | AS69: 0.018136779 | AT69: 0.018081436 | AU69: 0.018028493 | AV69: 0.017977969 | AW69: 0.017929885 | AX69: 0.017884261 | AY69: 0.017841116 | AZ69: 0.017800468 | BA69: 0.017762334 | BB69: 0.01772673 | BC69: 0.017693672 | BD69: 0.017663173 | BE69: 0.017635247 | BF69: 0.017609907 | BG69: 0.017587163 | BH69: 0.017567025 | BI69: 0.017549503 | BJ69: 0.017534605

Sheet Plot
A1: Portfolio Return | B1: Portfolio Standard Deviation
A2: {=INDEX('Portfolio Weights Returns'!$B$9:$BJ$69, INT((ROW(B1)-1)/COLUMNS('Portfolio Weights Returns'!$B$9:$BJ$69))+1,MOD(ROW(B1)-1,COLUMNS('Portfolio Weights Returns'!$B$9:$BJ$69))+1)} -> -0.0011949753 | B2: {=INDEX('Portfolio Weights Std'!$B$9:$BJ$69,INT((ROW(B1)-1)/COLUMNS('Portfolio Weights Std'!$B$9:$BJ$69))+1,MOD(ROW(B1)-1,COLUMNS('Portfolio Weights Std'!$B$9:$BJ$69))+1)} -> 0.030096389
A3: {=INDEX('Portfolio Weights Returns'!$B$9:$BJ$69, INT((ROW(A2)-1)/COLUMNS('Portfolio Weights Returns'!$B$9:$BJ$69))+1,MOD(ROW(A2)-1,COLUMNS('Portfolio Weights Returns'!$B$9:$BJ$69))+1)} -> -0.0011881941 | B3: {=INDEX('Portfolio Weights Std'!$B$9:$BJ$69,INT((ROW(A2)-1)/COLUMNS('Portfolio Weights Std'!$B$9:$BJ$69))+1,MOD(ROW(A2)-1,COLUMNS('Portfolio Weights Std'!$B$9:$BJ$69))+1)} -> 0.029920476
A4: {=INDEX('Portfolio Weights Returns'!$B$9:$BJ$69, INT((ROW(A3)-1)/COLUMNS('Portfolio Weights Returns'!$B$9:$BJ$69))+1,MOD(ROW(A3)-1,COLUMNS('Portfolio Weights Returns'!$B$9:$BJ$69))+1)} -> -0.001181413 | B4: {=INDEX('Portfolio Weights Std'!$B$9:$BJ$69,INT((ROW(A3)-1)/COLUMNS('Portfolio Weights Std'!$B$9:$BJ$69))+1,MOD(ROW(A3)-1,COLUMNS('Portfolio Weights Std'!$B$9:$BJ$69))+1)} -> 0.029745079
A5: {=INDEX('Portfolio Weights Returns'!$B$9:$BJ$69, INT((ROW(A4)-1)/COLUMNS('Portfolio Weights Returns'!$B$9:$BJ$69))+1,MOD(ROW(A4)-1,COLUMNS('Portfolio Weights Returns'!$B$9:$BJ$69))+1)} -> -0.0011746318 | B5: {=INDEX('Portfolio Weights Std'!$B$9:$BJ$69,INT((ROW(A4)-1)/COLUMNS('Portfolio Weights Std'!$B$9:$BJ$69))+1,MOD(ROW(A4)-1,COLUMNS('Portfolio Weights Std'!$B$9:$BJ$69))+1)} -> 0.029570207
A6: {=INDEX('Portfolio Weights Returns'!$B$9:$BJ$69, INT((ROW(A5)-1)/COLUMNS('Portfolio Weights Returns'!$B$9:$BJ$69))+1,MOD(ROW(A5)-1,COLUMNS('Portfolio Weights Returns'!$B$9:$BJ$69))+1)} -> -0.0011678506 | B6: {=INDEX('Portfolio Weights Std'!$B$9:$BJ$69,INT((ROW(A5)-1)/COLUMNS('Portfolio Weights Std'!$B$9:$BJ$69))+1,MOD(ROW(A5)-1,COLUMNS('Portfolio Weights Std'!$B$9:$BJ$69))+1)} -> 0.029395871
A7: {=INDEX('Portfolio Weights Returns'!$B$9:$BJ$69, INT((ROW(A6)-1)/COLUMNS('Portfolio Weights Returns'!$B$9:$BJ$69))+1,MOD(ROW(A6)-1,COLUMNS('Portfolio Weights Returns'!$B$9:$BJ$69))+1)} -> -0.0011610694 | B7: {=INDEX('Portfolio Weights Std'!$B$9:$BJ$69,INT((ROW(A6)-1)/COLUMNS('Portfolio Weights Std'!$B$9:$BJ$69))+1,MOD(ROW(A6)-1,COLUMNS('Portfolio Weights Std'!$B$9:$BJ$69))+1)} -> 0.029222078
A8: {=INDEX('Portfolio Weights Returns'!$B$9:$BJ$69, INT((ROW(A7)-1)/COLUMNS('Portfolio Weights Returns'!$B$9:$BJ$69))+1,MOD(ROW(A7)-1,COLUMNS('Portfolio Weights Returns'!$B$9:$BJ$69))+1)} -> -0.0011542883 | B8: {=INDEX('Portfolio Weights Std'!$B$9:$BJ$69,INT((ROW(A7)-1)/COLUMNS('Portfolio Weights Std'!$B$9:$BJ$69))+1,MOD(ROW(A7)-1,COLUMNS('Portfolio Weights Std'!$B$9:$BJ$69))+1)} -> 0.02904884
A9: {=INDEX('Portfolio Weights Returns'!$B$9:$BJ$69, INT((ROW(A8)-1)/COLUMNS('Portfolio Weights Returns'!$B$9:$BJ$69))+1,MOD(ROW(A8)-1,COLUMNS('Portfolio Weights Returns'!$B$9:$BJ$69))+1)} -> -0.0011475071 | B9: {=INDEX('Portfolio Weights Std'!$B$9:$BJ$69,INT((ROW(A8)-1)/COLUMNS('Portfolio Weights Std'!$B$9:$BJ$69))+1,MOD(ROW(A8)-1,COLUMNS('Portfolio Weights Std'!$B$9:$BJ$69))+1)} -> 0.028876166
A10: {=INDEX('Portfolio Weights Returns'!$B$9:$BJ$69, INT((ROW(A9)-1)/COLUMNS('Portfolio Weights Returns'!$B$9:$BJ$69))+1,MOD(ROW(A9)-1,COLUMNS('Portfolio Weights Returns'!$B$9:$BJ$69))+1)} -> -0.0011407259 | B10: {=INDEX('Portfolio Weights Std'!$B$9:$BJ$69,INT((ROW(A9)-1)/COLUMNS('Portfolio Weights Std'!$B$9:$BJ$69))+1,MOD(ROW(A9)-1,COLUMNS('Portfolio Weights Std'!$B$9:$BJ$69))+1)} -> 0.028704067
A11: {=INDEX('Portfolio Weights Returns'!$B$9:$BJ$69, INT((ROW(A10)-1)/COLUMNS('Portfolio Weights Returns'!$B$9:$BJ$69))+1,MOD(ROW(A10)-1,COLUMNS('Portfolio Weights Returns'!$B$9:$BJ$69))+1)} -> -0.0011339447 | B11: {=INDEX('Portfolio Weights Std'!$B$9:$BJ$69,INT((ROW(A10)-1)/COLUMNS('Portfolio Weights Std'!$B$9:$BJ$69))+1,MOD(ROW(A10)-1,COLUMNS('Portfolio Weights Std'!$B$9:$BJ$69))+1)} -> 0.028532552
A12: {=INDEX('Portfolio Weights Returns'!$B$9:$BJ$69, INT((ROW(A11)-1)/COLUMNS('Portfolio Weights Returns'!$B$9:$BJ$69))+1,MOD(ROW(A11)-1,COLUMNS('Portfolio Weights Returns'!$B$9:$BJ$69))+1)} -> -0.0011271636 | B12: {=INDEX('Portfolio Weights Std'!$B$9:$BJ$69,INT((ROW(A11)-1)/COLUMNS('Portfolio Weights Std'!$B$9:$BJ$69))+1,MOD(ROW(A11)-1,COLUMNS('Portfolio Weights Std'!$B$9:$BJ$69))+1)} -> 0.028361633
A13: {=INDEX('Portfolio Weights Returns'!$B$9:$BJ$69, INT((ROW(A12)-1)/COLUMNS('Portfolio Weights Returns'!$B$9:$BJ$69))+1,MOD(ROW(A12)-1,COLUMNS('Portfolio Weights Returns'!$B$9:$BJ$69))+1)} -> -0.0011203824 | B13: {=INDEX('Portfolio Weights Std'!$B$9:$BJ$69,INT((ROW(A12)-1)/COLUMNS('Portfolio Weights Std'!$B$9:$BJ$69))+1,MOD(ROW(A12)-1,COLUMNS('Portfolio Weights Std'!$B$9:$BJ$69))+1)} -> 0.02819132
A14: {=INDEX('Portfolio Weights Returns'!$B$9:$BJ$69, INT((ROW(A13)-1)/COLUMNS('Portfolio Weights Returns'!$B$9:$BJ$69))+1,MOD(ROW(A13)-1,COLUMNS('Portfolio Weights Returns'!$B$9:$BJ$69))+1)} -> -0.0011136012 | B14: {=INDEX('Portfolio Weights Std'!$B$9:$BJ$69,INT((ROW(A13)-1)/COLUMNS('Portfolio Weights Std'!$B$9:$BJ$69))+1,MOD(ROW(A13)-1,COLUMNS('Portfolio Weights Std'!$B$9:$BJ$69))+1)} -> 0.028021624
... A3722: {=INDEX('Portfolio Weights Returns'!$B$9:$BJ$69, INT((ROW(A3721)-1)/COLUMNS('Portfolio Weights Returns'!$B$9:$BJ$69))+1,MOD(ROW(A3721)-1,COLUMNS('Portfolio Weights Returns'!$B$9:$BJ$69))+1)} -> -0.0003936524 | B3722: {=INDEX('Portfolio Weights Std'!$B$9:$BJ$69,INT((ROW(A3721)-1)/COLUMNS('Portfolio Weights Std'!$B$9:$BJ$69))+1,MOD(ROW(A3721)-1,COLUMNS('Portfolio Weights Std'!$B$9:$BJ$69))+1)} -> 0.017534605

Sheet Analytical MVP
A1: Portfolio Return | B1: Portfolio Standard Dev | C1: w1 | D1: w2 | E1: w3 | F1: Efficient
A2: {=INDEX('Portfolio Weights Returns'!$B$9:$BJ$69, INT((ROW(A1)-1)/COLUMNS('Portfolio Weights Returns'!$B$9:$BJ$69))+1,MOD(ROW(A1)-1,COLUMNS('Portfolio Weights Returns'!$B$9:$BJ$69))+1)} -> -0.0011949753 | B2: 0.0153 | C2: 0.3 | D2: 0.04 | E2: =1-D2-C2 -> 0.66 | F2: {=IF(A2=MAX(IF(ROUND($B$2:$B$3722,4)=ROUND(B2,4),$A$2:$A$3722)),"Efficient","Inefficient")} -> Inefficient | I2: Minimum Variance Portfolio
A3: {=INDEX('Portfolio Weights Returns'!$B$9:$BJ$69, INT((ROW(A2)-1)/COLUMNS('Portfolio Weights Returns'!$B$9:$BJ$69))+1,MOD(ROW(A2)-1,COLUMNS('Portfolio Weights Returns'!$B$9:$BJ$69))+1)} -> -0.0011881941 | B3: 0.0153 | C3: 0.3 | D3: 0.05 | E3: =1-D3-C3 -> 0.65 | F3: {=IF(A3=MAX(IF(ROUND($B$2:$B$3722,4)=ROUND(B3,4),$A$2:$A$3722)),"Efficient","Inefficient")} -> Inefficient | I3: MVP Return | J3: =INDEX(A2:A3722, MATCH(MIN(B2:B3722), B2:B3722, 0)) -> -0.0011949753
A4: {=INDEX('Portfolio Weights Returns'!$B$9:$BJ$69, INT((ROW(A3)-1)/COLUMNS('Portfolio Weights Returns'!$B$9:$BJ$69))+1,MOD(ROW(A3)-1,COLUMNS('Portfolio Weights Returns'!$B$9:$BJ$69))+1)} -> -0.001181413 | B4: 0.0153 | C4: 0.3 | D4: 0.06 | E4: =1-D4-C4 -> 0.64 | F4: {=IF(A4=MAX(IF(ROUND($B$2:$B$3722,4)=ROUND(B4,4),$A$2:$A$3722)),"Efficient","Inefficient")} -> Inefficient | I4: MVP Std Dev | J4: =MIN(B2:B3722) -> 0.0153
A5: {=INDEX('Portfolio Weights Returns'!$B$9:$BJ$69, INT((ROW(A4)-1)/COLUMNS('Portfolio Weights Returns'!$B$9:$BJ$69))+1,MOD(ROW(A4)-1,COLUMNS('Portfolio Weights Returns'!$B$9:$BJ$69))+1)} -> -0.0011746318 | B5: 0.0153 | C5: 0.3 | D5: 0.07 | E5: =1-D5-C5 -> 0.63 | F5: {=IF(A5=MAX(IF(ROUND($B$2:$B$3722,4)=ROUND(B5,4),$A$2:$A$3722)),"Efficient","Inefficient")} -> Inefficient | I5: MVP Var | J5: =J4^2 -> 0.00023409
A6: {=INDEX('Portfolio Weights Returns'!$B$9:$BJ$69, INT((ROW(A5)-1)/COLUMNS('Portfolio Weights Returns'!$B$9:$BJ$69))+1,MOD(ROW(A5)-1,COLUMNS('Portfolio Weights Returns'!$B$9:$BJ$69))+1)} -> -0.0011678506 | B6: 0.0153 | C6: 0.3 | D6: 0.08 | E6: =1-D6-C6 -> 0.62 | F6: {=IF(A6=MAX(IF(ROUND($B$2:$B$3722,4)=ROUND(B6,4),$A$2:$A$3722)),"Efficient","Inefficient")} -> Inefficient
A7: {=INDEX('Portfolio Weights Returns'!$B$9:$BJ$69, INT((ROW(A6)-1)/COLUMNS('Portfolio Weights Returns'!$B$9:$BJ$69))+1,MOD(ROW(A6)-1,COLUMNS('Portfolio Weights Returns'!$B$9:$BJ$69))+1)} -> -0.0011610694 | B7: 0.0153 | C7: 0.3 | D7: 0.09 | E7: =1-D7-C7 -> 0.61 | F7: {=IF(A7=MAX(IF(ROUND($B$2:$B$3722,4)=ROUND(B7,4),$A$2:$A$3722)),"Efficient","Inefficient")} -> Inefficient | I7: Weight
A8: {=INDEX('Portfolio Weights Returns'!$B$9:$BJ$69, INT((ROW(A7)-1)/COLUMNS('Portfolio Weights Returns'!$B$9:$BJ$69))+1,MOD(ROW(A7)-1,COLUMNS('Portfolio Weights Returns'!$B$9:$BJ$69))+1)} -> -0.0011542883 | B8: 0.0153 | C8: 0.3 | D8: 0.1 | E8: =1-D8-C8 -> 0.6 | F8: {=IF(A8=MAX(IF(ROUND($B$2:$B$3722,4)=ROUND(B8,4),$A$2:$A$3722)),"Efficient","Inefficient")} -> Efficient | I8: w1-MSFT | J8: =INDEX(C2:C3722, MATCH(MIN(B2:B3722), B2:B3722, 0)) -> 0.3
A9: {=INDEX('Portfolio Weights Returns'!$B$9:$BJ$69, INT((ROW(A8)-1)/COLUMNS('Portfolio Weights Returns'!$B$9:$BJ$69))+1,MOD(ROW(A8)-1,COLUMNS('Portfolio Weights Returns'!$B$9:$BJ$69))+1)} -> -0.0011475071 | B9: 0.0154 | C9: 0.3 | D9: 0.02 | E9: =1-D9-C9 -> 0.68 | F9: {=IF(A9=MAX(IF(ROUND($B$2:$B$3722,4)=ROUND(B9,4),$A$2:$A$3722)),"Efficient","Inefficient")} -> Inefficient | I9: w2-ORCL | J9: =INDEX(D2:D3722, MATCH(MIN(B2:B3722), B2:B3722, 0)) -> 0.04
A10: {=INDEX('Portfolio Weights Returns'!$B$9:$BJ$69, INT((ROW(A9)-1)/COLUMNS('Portfolio Weights Returns'!$B$9:$BJ$69))+1,MOD(ROW(A9)-1,COLUMNS('Portfolio Weights Returns'!$B$9:$BJ$69))+1)} -> -0.0011407259 | B10: 0.0154 | C10: 0.3 | D10: 0.03 | E10: =1-D10-C10 -> 0.67 | F10: {=IF(A10=MAX(IF(ROUND($B$2:$B$3722,4)=ROUND(B10,4),$A$2:$A$3722)),"Efficient","Inefficient")} -> Inefficient | I10: w3-SONY | J10: =INDEX(E2:E3722, MATCH(MIN(B2:B3722), B2:B3722, 0)) -> 0.66
A11: {=INDEX('Portfolio Weights Returns'!$B$9:$BJ$69, INT((ROW(A10)-1)/COLUMNS('Portfolio Weights Returns'!$B$9:$BJ$69))+1,MOD(ROW(A10)-1,COLUMNS('Portfolio Weights Returns'!$B$9:$BJ$69))+1)} -> -0.0011339447 | B11: 0.0154 | C11: 0.29 | D11: 0.04 | E11: =1-D11-C11 -> 0.67 | F11: {=IF(A11=MAX(IF(ROUND($B$2:$B$3722,4)=ROUND(B11,4),$A$2:$A$3722)),"Efficient","Inefficient")} -> Inefficient | I11: Sum of weights | J11: =SUM(J8:J10) -> 1
A12: {=INDEX('Portfolio Weights Returns'!$B$9:$BJ$69, INT((ROW(A11)-1)/COLUMNS('Portfolio Weights Returns'!$B$9:$BJ$69))+1,MOD(ROW(A11)-1,COLUMNS('Portfolio Weights Returns'!$B$9:$BJ$69))+1)} -> -0.0011271636 | B12: 0.0154 | C12: 0.29 | D12: 0.05 | E12: =1-D12-C12 -> 0.66 | F12: {=IF(A12=MAX(IF(ROUND($B$2:$B$3722,4)=ROUND(B12,4),$A$2:$A$3722)),"Efficient","Inefficient")} -> Inefficient
A13: {=INDEX('Portfolio Weights Returns'!$B$9:$BJ$69, INT((ROW(A12)-1)/COLUMNS('Portfolio Weights Returns'!$B$9:$BJ$69))+1,MOD(ROW(A12)-1,COLUMNS('Portfolio Weights Returns'!$B$9:$BJ$69))+1)} -> -0.0011203824 | B13: 0.0154 | C13: 0.29 | D13: 0.06 | E13: =1-D13-C13 -> 0.65 | F13: {=IF(A13=MAX(IF(ROUND($B$2:$B$3722,4)=ROUND(B13,4),$A$2:$A$3722)),"Efficient","Inefficient")} -> Inefficient
A14: {=INDEX('Portfolio Weights Returns'!$B$9:$BJ$69, INT((ROW(A13)-1)/COLUMNS('Portfolio Weights Returns'!$B$9:$BJ$69))+1,MOD(ROW(A13)-1,COLUMNS('Portfolio Weights Returns'!$B$9:$BJ$69))+1)} -> -0.0011136012 | B14: 0.0154 | C14: 0.28 | D14: 0.07 | E14: =1-D14-C14 -> 0.65 | F14: {=IF(A14=MAX(IF(ROUND($B$2:$B$3722,4)=ROUND(B14,4),$A$2:$A$3722)),"Efficient","Inefficient")} -> Inefficient
A15: {=INDEX('Portfolio Weights Returns'!$B$9:$BJ$69, INT((ROW(A14)-1)/COLUMNS('Portfolio Weights Returns'!$B$9:$BJ$69))+1,MOD(ROW(A14)-1,COLUMNS('Portfolio Weights Returns'!$B$9:$BJ$69))+1)} -> -0.00110682 | B15: 0.0154 | C15: 0.29 | D15: 0.07 | E15: =1-D15-C15 -> 0.64 | F15: {=IF(A15=MAX(IF(ROUND($B$2:$B$3722,4)=ROUND(B15,4),$A$2:$A$3722)),"Efficient","Inefficient")} -> Inefficient
A16: {=INDEX('Portfolio Weights Returns'!$B$9:$BJ$69, INT((ROW(A15)-1)/COLUMNS('Portfolio Weights Returns'!$B$9:$BJ$69))+1,MOD(ROW(A15)-1,COLUMNS('Portfolio Weights Returns'!$B$9:$BJ$69))+1)} -> -0.0011000389 | B16: 0.0154 | C16: 0.28 | D16: 0.08 | E16: =1-D16-C16 -> 0.64 | F16: {=IF(A16=MAX(IF(ROUND($B$2:$B$3722,4)=ROUND(B16,4),$A$2:$A$3722)),"Efficient","Inefficient")} -> Inefficient | I16: Averages
A17: {=INDEX('Portfolio Weights Returns'!$B$9:$BJ$69, INT((ROW(A16)-1)/COLUMNS('Portfolio Weights Returns'!$B$9:$BJ$69))+1,MOD(ROW(A16)-1,COLUMNS('Portfolio Weights Returns'!$B$9:$BJ$69))+1)} -> -0.0010932577 | B17: 0.0154 | C17: 0.29 | D17: 0.08 | E17: =1-D17-C17 -> 0.63 | F17: {=IF(A17=MAX(IF(ROUND($B$2:$B$3722,4)=ROUND(B17,4),$A$2:$A$3722)),"Efficient","Inefficient")} -> Inefficient | I17: Avg Std | J17: =AVERAGE(B2:B3722) -> 0.020387476
A18: {=INDEX('Portfolio Weights Returns'!$B$9:$BJ$69, INT((ROW(A17)-1)/COLUMNS('Portfolio Weights Returns'!$B$9:$BJ$69))+1,MOD(ROW(A17)-1,COLUMNS('Portfolio Weights Returns'!$B$9:$BJ$69))+1)} -> -0.0010864765 | B18: 0.0154 | C18: 0.28 | D18: 0.09 | E18: =1-D18-C18 -> 0.63 | F18: {=IF(A18=MAX(IF(ROUND($B$2:$B$3722,4)=ROUND(B18,4),$A$2:$A$3722)),"Efficient","Inefficient")} -> Inefficient | I18: Avg Mean | J18: =MAX(B2:B3722) -> 0.0301
A19: {=INDEX('Portfolio Weights Returns'!$B$9:$BJ$69, INT((ROW(A18)-1)/COLUMNS('Portfolio Weights Returns'!$B$9:$BJ$69))+1,MOD(ROW(A18)-1,COLUMNS('Portfolio Weights Returns'!$B$9:$BJ$69))+1)} -> -0.0010796953 | B19: 0.0154 | C19: 0.29 | D19: 0.09 | E19: =1-D19-C19 -> 0.62 | F19: {=IF(A19=MAX(IF(ROUND($B$2:$B$3722,4)=ROUND(B19,4),$A$2:$A$3722)),"Efficient","Inefficient")} -> Inefficient
A20: {=INDEX('Portfolio Weights Returns'!$B$9:$BJ$69, INT((ROW(A19)-1)/COLUMNS('Portfolio Weights Returns'!$B$9:$BJ$69))+1,MOD(ROW(A19)-1,COLUMNS('Portfolio Weights Returns'!$B$9:$BJ$69))+1)} -> -0.0010729142 | B20: 0.0154 | C20: 0.29 | D20: 0.1 | E20: =1-D20-C20 -> 0.61 | F20: {=IF(A20=MAX(IF(ROUND($B$2:$B$3722,4)=ROUND(B20,4),$A$2:$A$3722)),"Efficient","Inefficient")} -> Inefficient
A21: {=INDEX('Portfolio Weights Returns'!$B$9:$BJ$69, INT((ROW(A20)-1)/COLUMNS('Portfolio Weights Returns'!$B$9:$BJ$69))+1,MOD(ROW(A20)-1,COLUMNS('Portfolio Weights Returns'!$B$9:$BJ$69))+1)} -> -0.001066133 | B21: 0.0154 | C21: 0.29 | D21: 0.11 | E21: =1-D21-C21 -> 0.6 | F21: {=IF(A21=MAX(IF(ROUND($B$2:$B$3722,4)=ROUND(B21,4),$A$2:$A$3722)),"Efficient","Inefficient")} -> Inefficient
A22: {=INDEX('Portfolio Weights Returns'!$B$9:$BJ$69, INT((ROW(A21)-1)/COLUMNS('Portfolio Weights Returns'!$B$9:$BJ$69))+1,MOD(ROW(A21)-1,COLUMNS('Portfolio Weights Returns'!$B$9:$BJ$69))+1)} -> -0.0010593518 | B22: 0.0154 | C22: 0.3 | D22: 0.11 | E22: =1-D22-C22 -> 0.59 | F22: {=IF(A22=MAX(IF(ROUND($B$2:$B$3722,4)=ROUND(B22,4),$A$2:$A$3722)),"Efficient","Inefficient")} -> Inefficient
A23: {=INDEX('Portfolio Weights Returns'!$B$9:$BJ$69, INT((ROW(A22)-1)/COLUMNS('Portfolio Weights Returns'!$B$9:$BJ$69))+1,MOD(ROW(A22)-1,COLUMNS('Portfolio Weights Returns'!$B$9:$BJ$69))+1)} -> -0.0010525707 | B23: 0.0154 | C23: 0.3 | D23: 0.12 | E23: =1-D23-C23 -> 0.58 | F23: {=IF(A23=MAX(IF(ROUND($B$2:$B$3722,4)=ROUND(B23,4),$A$2:$A$3722)),"Efficient","Inefficient")} -> Inefficient
A24: {=INDEX('Portfolio Weights Returns'!$B$9:$BJ$69, INT((ROW(A23)-1)/COLUMNS('Portfolio Weights Returns'!$B$9:$BJ$69))+1,MOD(ROW(A23)-1,COLUMNS('Portfolio Weights Returns'!$B$9:$BJ$69))+1)} -> -0.0010457895 | B24: 0.0154 | C24: 0.3 | D24: 0.13 | E24: =1-D24-C24 -> 0.57 | F24: {=IF(A24=MAX(IF(ROUND($B$2:$B$3722,4)=ROUND(B24,4),$A$2:$A$3722)),"Efficient","Inefficient")} -> Efficient
A25: {=INDEX('Portfolio Weights Returns'!$B$9:$BJ$69, INT((ROW(A24)-1)/COLUMNS('Portfolio Weights Returns'!$B$9:$BJ$69))+1,MOD(ROW(A24)-1,COLUMNS('Portfolio Weights Returns'!$B$9:$BJ$69))+1)} -> -0.0010390083 | B25: 0.0155 | C25: 0.3 | D25: 0 | E25: =1-D25-C25 -> 0.7 | F25: {=IF(A25=MAX(IF(ROUND($B$2:$B$3722,4)=ROUND(B25,4),$A$2:$A$3722)),"Efficient","Inefficient")} -> Inefficient
A26: {=INDEX('Portfolio Weights Returns'!$B$9:$BJ$69, INT((ROW(A25)-1)/COLUMNS('Portfolio Weights Returns'!$B$9:$BJ$69))+1,MOD(ROW(A25)-1,COLUMNS('Portfolio Weights Returns'!$B$9:$BJ$69))+1)} -> -0.0010322271 | B26: 0.0155 | C26: 0.3 | D26: 0.01 | E26: =1-D26-C26 -> 0.69 | F26: {=IF(A26=MAX(IF(ROUND($B$2:$B$3722,4)=ROUND(B26,4),$A$2:$A$3722)),"Efficient","Inefficient")} -> Inefficient
A27: {=INDEX('Portfolio Weights Returns'!$B$9:$BJ$69, INT((ROW(A26)-1)/COLUMNS('Portfolio Weights Returns'!$B$9:$BJ$69))+1,MOD(ROW(A26)-1,COLUMNS('Portfolio Weights Returns'!$B$9:$BJ$69))+1)} -> -0.001025446 | B27: 0.0155 | C27: 0.29 | D27: 0.02 | E27: =1-D27-C27 -> 0.69 | F27: {=IF(A27=MAX(IF(ROUND($B$2:$B$3722,4)=ROUND(B27,4),$A$2:$A$3722)),"Efficient","Inefficient")} -> Inefficient
A28: {=INDEX('Portfolio Weights Returns'!$B$9:$BJ$69, INT((ROW(A27)-1)/COLUMNS('Portfolio Weights Returns'!$B$9:$BJ$69))+1,MOD(ROW(A27)-1,COLUMNS('Portfolio Weights Returns'!$B$9:$BJ$69))+1)} -> -0.0010186648 | B28: 0.0155 | C28: 0.29 | D28: 0.03 | E28: =1-D28-C28 -> 0.68 | F28: {=IF(A28=MAX(IF(ROUND($B$2:$B$3722,4)=ROUND(B28,4),$A$2:$A$3722)),"Efficient","Inefficient")} -> Inefficient
A29: {=INDEX('Portfolio Weights Returns'!$B$9:$BJ$69, INT((ROW(A28)-1)/COLUMNS('Portfolio Weights Returns'!$B$9:$BJ$69))+1,MOD(ROW(A28)-1,COLUMNS('Portfolio Weights Returns'!$B$9:$BJ$69))+1)} -> -0.0010118836 | B29: 0.0155 | C29: 0.28 | D29: 0.04 | E29: =1-D29-C29 -> 0.68 | F29: {=IF(A29=MAX(IF(ROUND($B$2:$B$3722,4)=ROUND(B29,4),$A$2:$A$3722)),"Efficient","Inefficient")} -> Inefficient
A30: {=INDEX('Portfolio Weights Returns'!$B$9:$BJ$69, INT((ROW(A29)-1)/COLUMNS('Portfolio Weights Returns'!$B$9:$BJ$69))+1,MOD(ROW(A29)-1,COLUMNS('Portfolio Weights Returns'!$B$9:$BJ$69))+1)} -> -0.0010051024 | B30: 0.0155 | C30: 0.28 | D30: 0.05 | E30: =1-D30-C30 -> 0.67 | F30: {=IF(A30=MAX(IF(ROUND($B$2:$B$3722,4)=ROUND(B30,4),$A$2:$A$3722)),"Efficient","Inefficient")} -> Inefficient
... A1949: {=INDEX('Portfolio Weights Returns'!$B$9:$BJ$69, INT((ROW(A1948)-1)/COLUMNS('Portfolio Weights Returns'!$B$9:$BJ$69))+1,MOD(ROW(A1948)-1,COLUMNS('Portfolio Weights Returns'!$B$9:$BJ$69))+1)} -> -0.00061142912 | B1949: 0.0203 | C1949: 0.16 | D1949: -0.2 | E1949: =1-D1949-C1949 -> 1.04 | F1949: {=IF(A1949=MAX(IF(ROUND($B$2:$B$3722,4)=ROUND(B1949,4),$A$2:$A$3722)),"Efficient","Inefficient")} -> Inefficient
A1950: {=INDEX('Portfolio Weights Returns'!$B$9:$BJ$69, INT((ROW(A1949)-1)/COLUMNS('Portfolio Weights Returns'!$B$9:$BJ$69))+1,MOD(ROW(A1949)-1,COLUMNS('Portfolio Weights Returns'!$B$9:$BJ$69))+1)} -> -0.00060464795 | B1950: 0.0203 | C1950: 0.14 | D1950: -0.19 | E1950: =1-D1950-C1950 -> 1.05 | F1950: {=IF(A1950=MAX(IF(ROUND($B$2:$B$3722,4)=ROUND(B1950,4),$A$2:$A$3722)),"Efficient","Inefficient")} -> Inefficient | H1950: {=INDEX('Portfolio Weights Returns'!$B$9:$BJ$69, INT((ROW(H1949)-1)/COLUMNS('Portfolio Weights Returns'!$B$9:$BJ$69))+1,MOD(ROW(H1949)-1,COLUMNS('Portfolio Weights Returns'!$B$9:$BJ$69))+1)} -> -0.00060464795 | I1950: 0.0203
